Workbook

Sheet Overview
A1: MISSING VOICE LINES · MISSIONS 1–4
A2: Source: First try.zip | Character tabs follow mission / phase order.
A4: Recording checklist | B4: =COUNTA('Missing lines'!$D$5:$D$80) -> 76 | C4: Text-only / review | D4: =COUNTA('Text-only review'!$D$5:$D$25) -> 21 | E4: Matched audio | F4: =COUNTIF('Registry audit'!$E$5:$E$177,"Audio matched") -> 119
A5: 52 registered gaps + 24 unregistered spoken lines.
A7: Mission | B7: Missing audio | C7: Unregistered | D7: Recording total | E7: Text-only / review | F7: Done
A8: 1 | B8: =COUNTIFS('Missing lines'!$B$5:$B$80,A8,'Missing lines'!$G$5:$G$80,"No matched audio") -> 0 | C8: =COUNTIFS('Missing lines'!$B$5:$B$80,A8,'Missing lines'!$G$5:$G$80,"Not in voice manifest") -> 3 | D8: =B8+C8 -> 3 | E8: =COUNTIF('Text-only review'!$B$5:$B$25,A8) -> 12 | F8: =COUNTIFS('Missing lines'!$B$5:$B$80,A8,'Missing lines'!$H$5:$H$80,"Recorded") -> 0
A9: 2 | B9: =COUNTIFS('Missing lines'!$B$5:$B$80,A9,'Missing lines'!$G$5:$G$80,"No matched audio") -> 3 | C9: =COUNTIFS('Missing lines'!$B$5:$B$80,A9,'Missing lines'!$G$5:$G$80,"Not in voice manifest") -> 5 | D9: =B9+C9 -> 8 | E9: =COUNTIF('Text-only review'!$B$5:$B$25,A9) -> 4 | F9: =COUNTIFS('Missing lines'!$B$5:$B$80,A9,'Missing lines'!$H$5:$H$80,"Recorded") -> 0
A10: 3 | B10: =COUNTIFS('Missing lines'!$B$5:$B$80,A10,'Missing lines'!$G$5:$G$80,"No matched audio") -> 40 | C10: =COUNTIFS('Missing lines'!$B$5:$B$80,A10,'Missing lines'!$G$5:$G$80,"Not in voice manifest") -> 9 | D10: =B10+C10 -> 49 | E10: =COUNTIF('Text-only review'!$B$5:$B$25,A10) -> 2 | F10: =COUNTIFS('Missing lines'!$B$5:$B$80,A10,'Missing lines'!$H$5:$H$80,"Recorded") -> 0
A11: 4 | B11: =COUNTIFS('Missing lines'!$B$5:$B$80,A11,'Missing lines'!$G$5:$G$80,"No matched audio") -> 9 | C11: =COUNTIFS('Missing lines'!$B$5:$B$80,A11,'Missing lines'!$G$5:$G$80,"Not in voice manifest") -> 7 | D11: =B11+C11 -> 16 | E11: =COUNTIF('Text-only review'!$B$5:$B$25,A11) -> 3 | F11: =COUNTIFS('Missing lines'!$B$5:$B$80,A11,'Missing lines'!$H$5:$H$80,"Recorded") -> 0
A14: Character / voice | B14: Recording rows | C14: Text-only / review | D14: Character tab | E14: Scope
A15: Balaceanu | B15: =COUNTIF('Missing lines'!$E$5:$E$80,A15) -> 12 | C15: =COUNTIF('Text-only review'!$E$5:$E$25,A15) -> 0 | D15: Balaceanu | E15: Actor / NPC
A16: Biribel | B16: =COUNTIF('Missing lines'!$E$5:$E$80,A16) -> 3 | C16: =COUNTIF('Text-only review'!$E$5:$E$25,A16) -> 0 | D16: Biribel | E16: Actor / NPC
A17: Darius | B17: =COUNTIF('Missing lines'!$E$5:$E$80,A17) -> 1 | C17: =COUNTIF('Text-only review'!$E$5:$E$25,A17) -> 0 | D17: Darius | E17: Actor / NPC
A18: Gabi | B18: =COUNTIF('Missing lines'!$E$5:$E$80,A18) -> 1 | C18: =COUNTIF('Text-only review'!$E$5:$E$25,A18) -> 0 | D18: Gabi | E18: Actor / NPC
A19: Hungry Kid | B19: =COUNTIF('Missing lines'!$E$5:$E$80,A19) -> 0 | C19: =COUNTIF('Text-only review'!$E$5:$E$25,A19) -> 2 | D19: Hungry Kid | E19: Actor / NPC
A20: IPA Dispatch | B20: =COUNTIF('Missing lines'!$E$5:$E$80,A20) -> 1 | C20: =COUNTIF('Text-only review'!$E$5:$E$25,A20) -> 0 | D20: IPA Dispatch | E20: Actor / NPC
A21: Intercept Operator | B21: =COUNTIF('Missing lines'!$E$5:$E$80,A21) -> 1 | C21: =COUNTIF('Text-only review'!$E$5:$E$25,A21) -> 0 | D21: Intercept Operator | E21: Actor / NPC
A22: Loyalist Comms | B22: =COUNTIF('Missing lines'!$E$5:$E$80,A22) -> 2 | C22: =COUNTIF('Text-only review'!$E$5:$E$25,A22) -> 0 | D22: Loyalist Comms | E22: Actor / NPC
A23: Maru | B23: =COUNTIF('Missing lines'!$E$5:$E$80,A23) -> 14 | C23: =COUNTIF('Text-only review'!$E$5:$E$25,A23) -> 0 | D23: Maru | E23: Actor / NPC
A24: Old Fisherman | B24: =COUNTIF('Missing lines'!$E$5:$E$80,A24) -> 0 | C24: =COUNTIF('Text-only review'!$E$5:$E$25,A24) -> 7 | D24: Old Fisherman | E24: Actor / NPC
A25: Old Woman | B25: =COUNTIF('Missing lines'!$E$5:$E$80,A25) -> 0 | C25: =COUNTIF('Text-only review'!$E$5:$E$25,A25) -> 3 | D25: Old Woman | E25: Actor / NPC
A26: PA System | B26: =COUNTIF('Missing lines'!$E$5:$E$80,A26) -> 1 | C26: =COUNTIF('Text-only review'!$E$5:$E$25,A26) -> 0 | D26: PA System | E26: Actor / NPC
... A32: Volkov | B32: =COUNTIF('Missing lines'!$E$5:$E$80,A32) -> 31 | C32: =COUNTIF('Text-only review'!$E$5:$E$25,A32) -> 0 | D32: Volkov | E32: Actor / NPC
A35: START HERE → Sources & Read me
A36: NEW_NNN / TEXT_NNN are checklist IDs, not game VO IDs.

Sheet Missing lines
A1: RECORDING CHECKLIST · ALL CHARACTERS
A2: Mission 1 → Mission 4 · Optional branches are included; ordering within free-play phases can vary.
A3: Use filters to select a character or mission. Existing VO IDs keep their original numbering.
A4: Order | B4: Mission | C4: Scene / trigger | D4: ID | E4: Character | F4: Exact line / dialogue | G4: Gap / action | H4: Tracking | I4: Notes | J4: Source file : line
A5: 1 | B5: 1 | C5: Warehouse safe: wrong-code hint | D5: NEW_001 | E5: Biribel | F5: The memos said something about a shipment number… | G5: Not in voice manifest | H5: To record | I5: Add an entry to VOICE_LINES with a new VO ID; recording alone will not resolve this text. Optional: plays after a wrong safe-code attempt (first, second, then third+). | J5: src/core/interactions.py:189
A6: 2 | B6: 1 | C6: Warehouse safe: wrong-code hint | D6: NEW_002 | E6: Biribel | F6: Shipment 7742. Only the last three digits. | G6: Not in voice manifest | H6: To record | I6: Add an entry to VOICE_LINES with a new VO ID; recording alone will not resolve this text. Optional: plays after a wrong safe-code attempt (first, second, then third+). | J6: src/core/interactions.py:191
A7: 3 | B7: 1 | C7: Warehouse safe: wrong-code hint | D7: NEW_003 | E7: Biribel | F7: 7… 4… 2. Has to be. | G7: Not in voice manifest | H7: To record | I7: Add an entry to VOICE_LINES with a new VO ID; recording alone will not resolve this text. Optional: plays after a wrong safe-code attempt (first, second, then third+). | J7: src/core/interactions.py:193
A8: 4 | B8: 2 | C8: Investigation: travel / equipment warning | D8: NEW_004 | E8: Vasile | F8: Route 12 opens into the checkpoint corridor. Stay slow. | G8: Not in voice manifest | H8: To record | I8: Add an entry to VOICE_LINES with a new VO ID; recording alone will not resolve this text. Travel triggers depend on route; shown in broad progression, not guaranteed trigger order. | J8: src/missions/m2/meta.py:579
A9: 5 | B9: 2 | C9: Investigation: blast overlook | D9: NEW_005 | E9: Gabi | F9: Blast pattern is too clean for a panic bombing. | G9: Not in voice manifest | H9: To record | I9: Add an entry to VOICE_LINES with a new VO ID; recording alone will not resolve this text. Travel triggers depend on route; shown in broad progression, not guaranteed trigger order. | J9: src/missions/m2/meta.py:591
A10: 6 | B10: 2 | C10: Investigation: south ditch static | D10: NEW_006 | E10: Darius | F10: Static is pooling down here. Something jammed the channel. | G10: Not in voice manifest | H10: To record | I10: Add an entry to VOICE_LINES with a new VO ID; recording alone will not resolve this text. Travel triggers depend on route; shown in broad progression, not guaranteed trigger order. | J10: src/missions/m2/meta.py:603
A11: 7 | B11: 2 | C11: Investigation: travel / equipment warning | D11: NEW_007 | E11: Vasile | F11: Government tread, checkpoint equipment... keep your heads down. | G11: Not in voice manifest | H11: To record | I11: Add an entry to VOICE_LINES with a new VO ID; recording alone will not resolve this text. Travel triggers depend on route; shown in broad progression, not guaranteed trigger order. | J11: src/missions/m2/meta.py:614
A12: 8 | B12: 2 | C12: Investigation: gantry flash preview | D12: NEW_008 | E12: Seby | F12: Did anyone else see that flash above the gantry? | G12: Not in voice manifest | H12: To record | I12: Add an entry to VOICE_LINES with a new VO ID; recording alone will not resolve this text. Travel triggers depend on route; shown in broad progression, not guaranteed trigger order. | J12: src/missions/m2/meta.py:625
A13: 9 | B13: 2 | C13: Ending: state broadcast | D13: VO_001 | E13: President Retardovici | F13: Route 12 will be remembered as the day KRAP discipline failed the nation. | G13: No matched audio | H13: To record | I13: Record clean; the game applies radio processing where needed. | J13: src/missions/m2/meta.py:103
A14: 10 | B14: 2 | C14: Ending: government review | D14: VO_002 | E14: Balaceanu | F14: Effective immediately, KRAP operations in the highway corridor fall under government review. | G14: No matched audio | H14: To record | I14: Record clean; the game applies radio processing where needed. | J14: src/missions/m2/meta.py:109
A15: 11 | B15: 2 | C15: Capture bridge: IPA dispatch | D15: VO_003 | E15: IPA Dispatch | F15: All units. The KRAP operator is the primary suspect. Bring him in. Authorization IPA-Code Omega. | G15: No matched audio | H15: To record | I15: Record clean; the game applies radio processing where needed. | J15: src/missions/m2/meta.py:141
A16: 12 | B16: 3 | C16: Cold open: monitor taunt | D16: VO_005 | E16: Balaceanu | F16: You told them I was a coward, Biribel. A fake. Tonight I tell the nation what you are. | G16: No matched audio | H16: To record | I16: Record clean; the game applies radio processing where needed. | J16: src/missions/m3/meta.py:99
... A80: 76 | B80: 4 | C80: Ending: Maru silhouette | D80: VO_081 | E80: Maru | F80: And the man on the screen smiles. The country is cheering the wrong name tonight. | G80: No matched audio | H80: To record | I80: Record clean; the game applies radio processing where needed. | J80: src/missions/m4/meta.py:161

Sheet Text-only review
A1: TEXT-ONLY REVIEW
A2: Separate from required actor recordings: text-only conversations, system captions, or implementation review.
A3: Use filters to select a character or mission. Existing VO IDs keep their original numbering.
A4: Order | B4: Mission | C4: Scene / trigger | D4: ID | E4: Character | F4: Exact line / dialogue | G4: Gap / action | H4: Tracking | I4: Notes | J4: Source file : line
A5: 1 | B5: 1 | C5: Slum: conversation without rations | D5: TEXT_001 | E5: Hungry Kid | F5: cough... I haven't eaten in two days. Do you have any food, sir? | G5: Text-only; no VO hook | H5: Review | I5: No manifest entry and no voice-playback call. Add playback plus a VO ID only if you intend this NPC dialogue to be voiced. Optional interaction; local order depends on the player. | J5: src/missions/walking_sim.py:224
A6: 2 | B6: 1 | C6: Slum: repeat interaction | D6: TEXT_002 | E6: Hungry Kid | F6: Thanks for the food, sir! Be careful, the guards are on high alert. | G6: Text-only; no VO hook | H6: Review | I6: No manifest entry and no voice-playback call. Add playback plus a VO ID only if you intend this NPC dialogue to be voiced. Optional interaction; local order depends on the player. | J6: src/missions/walking_sim.py:232
A7: 3 | B7: 1 | C7: Slum: conversation without rations | D7: TEXT_003 | E7: Old Woman | F7: They took everything... even the well water is contaminated. A dry throat and an empty stomach, that's our reward. | G7: Text-only; no VO hook | H7: Review | I7: No manifest entry and no voice-playback call. Add playback plus a VO ID only if you intend this NPC dialogue to be voiced. Optional interaction; local order depends on the player. | J7: src/missions/walking_sim.py:242
A8: 4 | B8: 1 | C8: Slum: food-gift response | D8: TEXT_004 | E8: Old Woman | F8: Bless you, soldier. Listen closely... The guards at the warehouse safe use a security passcode. I saw them write it down on notes: 7 - 4 - 2. Remember it well. | G8: Text-only; no VO hook | H8: Review | I8: No manifest entry and no voice-playback call. Add playback plus a VO ID only if you intend this NPC dialogue to be voiced. Optional interaction; local order depends on the player. | J8: src/missions/walking_sim.py:246
A9: 5 | B9: 1 | C9: Slum: repeat interaction | D9: TEXT_005 | E9: Old Woman | F9: Remember, the code to the notebook safe is 742. | G9: Text-only; no VO hook | H9: Review | I9: No manifest entry and no voice-playback call. Add playback plus a VO ID only if you intend this NPC dialogue to be voiced. Optional interaction; local order depends on the player. | J9: src/missions/walking_sim.py:252
A10: 6 | B10: 1 | C10: Harbor: oil-rig attack | D10: TEXT_006 | E10: Old Fisherman | F10: Hear that engine? Too fast for a fishing boat. | G10: Text-only; no VO hook | H10: Review | I10: Timeline frame 135 (60 fps). _trigger_walk_dialogue only displays text; no manifest entry or voice-playback call. | J10: src/missions/walking_sim.py:1424
A11: 7 | B11: 1 | C11: Harbor: oil-rig attack | D11: TEXT_007 | E11: Old Fisherman | F11: They come in low during the rain. The rigs never see them until the first rocket. | G11: Text-only; no VO hook | H11: Review | I11: Timeline frame 360 (60 fps). _trigger_walk_dialogue only displays text; no manifest entry or voice-playback call. | J11: src/missions/walking_sim.py:1436
A12: 8 | B12: 1 | C12: Harbor: oil-rig attack | D12: TEXT_008 | E12: Old Fisherman | F12: There. Center rig's folding. | G12: Text-only; no VO hook | H12: Review | I12: Timeline frame 574 (60 fps). _trigger_walk_dialogue only displays text; no manifest entry or voice-playback call. | J12: src/missions/walking_sim.py:1466
A13: 9 | B13: 1 | C13: Harbor: oil-rig attack | D13: TEXT_009 | E13: Old Fisherman | F13: Left rig's falling into the sea. | G13: Text-only; no VO hook | H13: Review | I13: Timeline frame 795 (60 fps). _trigger_walk_dialogue only displays text; no manifest entry or voice-playback call. | J13: src/missions/walking_sim.py:1472
A14: 10 | B14: 1 | C14: Harbor: oil-rig attack | D14: TEXT_010 | E14: Old Fisherman | F14: Now the last one burns. Three fires on the horizon. | G14: Text-only; no VO hook | H14: Review | I14: Timeline frame 1030 (60 fps). _trigger_walk_dialogue only displays text; no manifest entry or voice-playback call. | J14: src/missions/walking_sim.py:1478
A15: 11 | B15: 1 | C15: Harbor: oil-rig attack | D15: TEXT_011 | E15: Old Fisherman | F15: Third time this month. KRAP watches until the oil stops moving. | G15: Text-only; no VO hook | H15: Review | I15: Timeline frame 1220 (60 fps). _trigger_walk_dialogue only displays text; no manifest entry or voice-playback call. | J15: src/missions/walking_sim.py:1452
A16: 12 | B16: 1 | C16: Harbor: oil-rig attack | D16: TEXT_012 | E16: Old Fisherman | F16: You're new. You'll learn. | G16: Text-only; no VO hook | H16: Review | I16: Timeline frame 1600 (60 fps). _trigger_walk_dialogue only displays text; no manifest entry or voice-playback call. | J16: src/missions/walking_sim.py:1459
... A25: 21 | B25: 4 | C25: System radio / objective notice | D25: TEXT_021 | E25: System | F25: All units - the studio transmitter is live. Do not let it go dark. | G25: Generic system text; review | H25: Review | I25: Uses the radio-text channel but has no assigned actor or manifest entry. Voice only if wanted; add a VO ID first. | J25: src/missions/m4/flow.py:607

Sheet Balaceanu
A1: BALACEANU
A2: Mission 1 → Mission 4 · Optional branches are included; ordering within free-play phases can vary.
A3: Character view. Update Tracking on the master Missing lines / Text-only review tab.
A4: Order | B4: Mission | C4: Scene / trigger | D4: ID | E4: Character | F4: Exact line / dialogue | G4: Gap / action | H4: Tracking | I4: Notes | J4: Source file : line
A5: 10 | B5: 2 | C5: Ending: government review | D5: VO_002 | E5: Balaceanu | F5: Effective immediately, KRAP operations in the highway corridor fall under government review. | G5: No matched audio | H5: ='Missing lines'!H14 -> To record | I5: Record clean; the game applies radio processing where needed. | J5: src/missions/m2/meta.py:109
A6: 12 | B6: 3 | C6: Cold open: monitor taunt | D6: VO_005 | E6: Balaceanu | F6: You told them I was a coward, Biribel. A fake. Tonight I tell the nation what you are. | G6: No matched audio | H6: ='Missing lines'!H16 -> To record | I6: Record clean; the game applies radio processing where needed. | J6: src/missions/m3/meta.py:99
A7: 13 | B7: 3 | C7: Cold open: deadline / repeated interrogation tape | D7: VO_006 | E7: Balaceanu | F7: When the address ends, so do you. That is not a threat. That is a schedule. | G7: No matched audio | H7: ='Missing lines'!H17 -> To record | I7: Record clean; the game applies radio processing where needed. Shared by the intro and interrogation; also covers duplicate VO_014. | J7: src/missions/m3/meta.py:113; src/missions/m3/meta.py:388
A8: 14 | B8: 3 | C8: Interrogation: monitor tape | D8: VO_010 | E8: Balaceanu | F8: Six years I have waited to show the nation what a KRAP lie looks like. Up close. On camera. | G8: No matched audio | H8: ='Missing lines'!H18 -> To record | I8: Record clean; the game applies radio processing where needed. | J8: src/missions/m3/meta.py:360
A9: 15 | B9: 3 | C9: Interrogation: monitor tape | D9: VO_011 | E9: Balaceanu | F9: They'll see your face, Biribel. They'll hear Route 12. And then they'll see what happens to people who leak rumors about their Prime Minister. | G9: No matched audio | H9: ='Missing lines'!H19 -> To record | I9: Record clean; the game applies radio processing where needed. | J9: src/missions/m3/meta.py:362
A10: 16 | B10: 3 | C10: Interrogation: monitor tape | D10: VO_012 | E10: Balaceanu | F10: At twenty-two hundred, the President names you. Route 12. By face. I made sure the file is... thorough. | G10: No matched audio | H10: ='Missing lines'!H20 -> To record | I10: Record clean; the game applies radio processing where needed. | J10: src/missions/m3/meta.py:369
A11: 17 | B11: 3 | C11: Interrogation: tape response | D11: VO_013 | E11: Balaceanu | F11: Oh, save it. This tape is one-way. I'm told the acoustics in here are... unkind. | G11: No matched audio | H11: ='Missing lines'!H21 -> To record | I11: Record clean; the game applies radio processing where needed. | J11: src/missions/m3/meta.py:386
A12: 41 | B12: 3 | C12: Archives → Kill Order: PA | D12: VO_008 | E12: Balaceanu | F12: Sweep teams: the prisoner is in the lobby levels. Free fire, my address begins at 22:00, and I will not be interrupted. | G12: No matched audio | H12: ='Missing lines'!H45 -> To record | I12: Record clean; the game applies radio processing where needed. | J12: src/missions/m3/meta.py:267
A13: 42 | B13: 3 | C13: Kill Order: scheduled PA | D13: VO_004 | E13: Balaceanu | F13: Sweep teams, report. The prisoner carries state property. My address begins at 22:00, and he will not outlive it. | G13: No matched audio | H13: ='Missing lines'!H46 -> To record | I13: Record clean; the game applies radio processing where needed. | J13: src/missions/m3/flow.py:955
A14: 56 | B14: 3 | C14: Kill Order → Broadcast: PA | D14: VO_009 | E14: Balaceanu | F14: The prisoner is contained. At twenty-two hundred I will close the matter of Route 12, on camera, before the nation. | G14: No matched audio | H14: ='Missing lines'!H60 -> To record | I14: Record clean; the game applies radio processing where needed. | J14: src/missions/m3/meta.py:288
A15: 58 | B15: 3 | C15: Broadcast timeout: fail cutscene | D15: VO_015 | E15: Balaceanu | F15: Twenty-two hundred. The address is finished. The prisoner is contained. Route 12 is closed. | G15: No matched audio | H15: ='Missing lines'!H62 -> To record | I15: Record clean; the game applies radio processing where needed. Only when the broadcast timer expires. | J15: src/missions/m3/meta.py:483
A16: 59 | B16: 3 | C16: Ending: feed cut | D16: VO_007 | E16: Balaceanu | F16: What is this? Cut the feed. CUT THE FEED! | G16: No matched audio | H16: ='Missing lines'!H63 -> To record | I16: Record clean; the game applies radio processing where needed. | J16: src/missions/m3/meta.py:140

Sheet Biribel
A1: BIRIBEL
A2: Mission 1 → Mission 4 · Optional branches are included; ordering within free-play phases can vary.
A3: Character view. Update Tracking on the master Missing lines / Text-only review tab.
A4: Order | B4: Mission | C4: Scene / trigger | D4: ID | E4: Character | F4: Exact line / dialogue | G4: Gap / action | H4: Tracking | I4: Notes | J4: Source file : line
A5: 1 | B5: 1 | C5: Warehouse safe: wrong-code hint | D5: NEW_001 | E5: Biribel | F5: The memos said something about a shipment number… | G5: Not in voice manifest | H5: ='Missing lines'!H5 -> To record | I5: Add an entry to VOICE_LINES with a new VO ID; recording alone will not resolve this text. Optional: plays after a wrong safe-code attempt (first, second, then third+). | J5: src/core/interactions.py:189
A6: 2 | B6: 1 | C6: Warehouse safe: wrong-code hint | D6: NEW_002 | E6: Biribel | F6: Shipment 7742. Only the last three digits. | G6: Not in voice manifest | H6: ='Missing lines'!H6 -> To record | I6: Add an entry to VOICE_LINES with a new VO ID; recording alone will not resolve this text. Optional: plays after a wrong safe-code attempt (first, second, then third+). | J6: src/core/interactions.py:191
A7: 3 | B7: 1 | C7: Warehouse safe: wrong-code hint | D7: NEW_003 | E7: Biribel | F7: 7… 4… 2. Has to be. | G7: Not in voice manifest | H7: ='Missing lines'!H7 -> To record | I7: Add an entry to VOICE_LINES with a new VO ID; recording alone will not resolve this text. Optional: plays after a wrong safe-code attempt (first, second, then third+). | J7: src/core/interactions.py:193

Sheet Darius
A1: DARIUS
A2: Mission 1 → Mission 4 · Optional branches are included; ordering within free-play phases can vary.
A3: Character view. Update Tracking on the master Missing lines / Text-only review tab.
A4: Order | B4: Mission | C4: Scene / trigger | D4: ID | E4: Character | F4: Exact line / dialogue | G4: Gap / action | H4: Tracking | I4: Notes | J4: Source file : line
A5: 6 | B5: 2 | C5: Investigation: south ditch static | D5: NEW_006 | E5: Darius | F5: Static is pooling down here. Something jammed the channel. | G5: Not in voice manifest | H5: ='Missing lines'!H10 -> To record | I5: Add an entry to VOICE_LINES with a new VO ID; recording alone will not resolve this text. Travel triggers depend on route; shown in broad progression, not guaranteed trigger order. | J5: src/missions/m2/meta.py:603

Sheet Gabi
A1: GABI
A2: Mission 1 → Mission 4 · Optional branches are included; ordering within free-play phases can vary.
A3: Character view. Update Tracking on the master Missing lines / Text-only review tab.
A4: Order | B4: Mission | C4: Scene / trigger | D4: ID | E4: Character | F4: Exact line / dialogue | G4: Gap / action | H4: Tracking | I4: Notes | J4: Source file : line
A5: 5 | B5: 2 | C5: Investigation: blast overlook | D5: NEW_005 | E5: Gabi | F5: Blast pattern is too clean for a panic bombing. | G5: Not in voice manifest | H5: ='Missing lines'!H9 -> To record | I5: Add an entry to VOICE_LINES with a new VO ID; recording alone will not resolve this text. Travel triggers depend on route; shown in broad progression, not guaranteed trigger order. | J5: src/missions/m2/meta.py:591

Sheet Hungry Kid
A1: HUNGRY KID
A2: Separate from required actor recordings: text-only conversations, system captions, or implementation review.
A3: Character view. Update Tracking on the master Missing lines / Text-only review tab.
A4: Order | B4: Mission | C4: Scene / trigger | D4: ID | E4: Character | F4: Exact line / dialogue | G4: Gap / action | H4: Tracking | I4: Notes | J4: Source file : line
A5: 1 | B5: 1 | C5: Slum: conversation without rations | D5: TEXT_001 | E5: Hungry Kid | F5: cough... I haven't eaten in two days. Do you have any food, sir? | G5: Text-only; no VO hook | H5: ='Text-only review'!H5 -> Review | I5: No manifest entry and no voice-playback call. Add playback plus a VO ID only if you intend this NPC dialogue to be voiced. Optional interaction; local order depends on the player. | J5: src/missions/walking_sim.py:224
A6: 2 | B6: 1 | C6: Slum: repeat interaction | D6: TEXT_002 | E6: Hungry Kid | F6: Thanks for the food, sir! Be careful, the guards are on high alert. | G6: Text-only; no VO hook | H6: ='Text-only review'!H6 -> Review | I6: No manifest entry and no voice-playback call. Add playback plus a VO ID only if you intend this NPC dialogue to be voiced. Optional interaction; local order depends on the player. | J6: src/missions/walking_sim.py:232

Sheet IPA Dispatch
A1: IPA DISPATCH
A2: Mission 1 → Mission 4 · Optional branches are included; ordering within free-play phases can vary.
A3: Character view. Update Tracking on the master Missing lines / Text-only review tab.
A4: Order | B4: Mission | C4: Scene / trigger | D4: ID | E4: Character | F4: Exact line / dialogue | G4: Gap / action | H4: Tracking | I4: Notes | J4: Source file : line
A5: 11 | B5: 2 | C5: Capture bridge: IPA dispatch | D5: VO_003 | E5: IPA Dispatch | F5: All units. The KRAP operator is the primary suspect. Bring him in. Authorization IPA-Code Omega. | G5: No matched audio | H5: ='Missing lines'!H15 -> To record | I5: Record clean; the game applies radio processing where needed. | J5: src/missions/m2/meta.py:141

Sheet Intercept Operator
A1: INTERCEPT OPERATOR
A2: Mission 1 → Mission 4 · Optional branches are included; ordering within free-play phases can vary.
A3: Character view. Update Tracking on the master Missing lines / Text-only review tab.
A4: Order | B4: Mission | C4: Scene / trigger | D4: ID | E4: Character | F4: Exact line / dialogue | G4: Gap / action | H4: Tracking | I4: Notes | J4: Source file : line
A5: 62 | B5: 4 | C5: Aftermath streets: timed radio beat | D5: NEW_019 | E5: Intercept Operator | F5: North border logged one vehicle at first light. Volkov ran. | G5: Not in voice manifest | H5: ='Missing lines'!H66 -> To record | I5: Add an entry to VOICE_LINES with a new VO ID; recording alone will not resolve this text. Intercept voice is not Volkov; the line reports his escape. | J5: src/missions/m4/flow.py:81

Sheet Loyalist Comms
A1: LOYALIST COMMS
A2: Mission 1 → Mission 4 · Optional branches are included; ordering within free-play phases can vary.
A3: Character view. Update Tracking on the master Missing lines / Text-only review tab.
A4: Order | B4: Mission | C4: Scene / trigger | D4: ID | E4: Character | F4: Exact line / dialogue | G4: Gap / action | H4: Tracking | I4: Notes | J4: Source file : line
A5: 74 | B5: 4 | C5: Transmitter siege: arrest / stand-down broadcast | D5: NEW_023 | E5: Loyalist Comms | F5: -say again- who gave the or- our channel's on every set- | G5: Not in voice manifest | H5: ='Missing lines'!H78 -> To record | I5: Add an entry to VOICE_LINES with a new VO ID; recording alone will not resolve this text. | J5: src/missions/m4/flow.py:338
A6: 75 | B6: 4 | C6: Transmitter siege: arrest / stand-down broadcast | D6: NEW_024 | E6: Loyalist Comms | F6: Fall back! Nobody dies for a man already in a cell. Break off! | G6: Not in voice manifest | H6: ='Missing lines'!H79 -> To record | I6: Add an entry to VOICE_LINES with a new VO ID; recording alone will not resolve this text. | J6: src/missions/m4/flow.py:342

Sheet Maru
A1: MARU
A2: Mission 1 → Mission 4 · Optional branches are included; ordering within free-play phases can vary.
A3: Character view. Update Tracking on the master Missing lines / Text-only review tab.
A4: Order | B4: Mission | C4: Scene / trigger | D4: ID | E4: Character | F4: Exact line / dialogue | G4: Gap / action | H4: Tracking | I4: Notes | J4: Source file : line
A5: 37 | B5: 3 | C5: Archives: Maru dead-drop contact | D5: VO_142 | E5: Maru | F5: The only unforged copy is under glass in the cold vault. Take it. Then the north stairwell, Balaceanu's sweep is already moving. | G5: No matched audio | H5: ='Missing lines'!H41 -> To record | I5: Record clean; the game applies radio processing where needed. | J5: src/missions/m3/flow.py:1829
A6: 39 | B6: 3 | C6: Archives: Vostral pickup / warning | D6: VO_145 | E6: Maru | F6: They will burn the wing when they realize. Don't look back. | G6: No matched audio | H6: ='Missing lines'!H43 -> To record | I6: Record clean; the game applies radio processing where needed. | J6: src/missions/m3/flow.py:1883
A7: 48 | B7: 3 | C7: Kill Order: dock gates / no van | D7: VO_150 | E7: Maru | F7: Dock gates open. No van waiting - move. | G7: No matched audio | H7: ='Missing lines'!H52 -> To record | I7: Record clean; the game applies radio processing where needed. Conditional gameplay / route; timing varies with play. | J7: src/missions/m3/sweep.py:290
A8: 52 | B8: 3 | C8: Dock holdout: crane / roof branch | D8: VO_156 | E8: Maru | F8: No van. The crane cage lifts to the roof line - hold the dock until it clears. | G8: No matched audio | H8: ='Missing lines'!H56 -> To record | I8: Record clean; the game applies radio processing where needed. Conditional gameplay / route; timing varies with play. | J8: src/missions/m3/sweep.py:877
A9: 54 | B9: 3 | C9: Exfil: roof branch | D9: VO_158 | E9: Maru | F9: Roof line confirmed. You're a ghost again, Biribel. Now - the broadcast. | G9: No matched audio | H9: ='Missing lines'!H58 -> To record | I9: Record clean; the game applies radio processing where needed. Conditional gameplay / route; timing varies with play. | J9: src/missions/m3/sweep.py:985
A10: 64 | B10: 4 | C10: Station: liaison meeting | D10: VO_073 | E10: Maru | F10: You got the file on air. Out here, that's not nothing. | G10: No matched audio | H10: ='Missing lines'!H68 -> To record | I10: Record clean; the game applies radio processing where needed. | J10: src/missions/m4/flow.py:140
A11: 65 | B11: 4 | C11: Station: liaison meeting | D11: VO_074 | E11: Maru | F11: His men have this block pinned. Hold the transmitter and let the arrest air. | G11: No matched audio | H11: ='Missing lines'!H69 -> To record | I11: Record clean; the game applies radio processing where needed. | J11: src/missions/m4/flow.py:142
A12: 66 | B12: 4 | C12: Station: liaison question | D12: VO_075 | E12: Maru | F12: One question before you bleed for this building - who are you fighting for? | G12: No matched audio | H12: ='Missing lines'!H70 -> To record | I12: Record clean; the game applies radio processing where needed. | J12: src/missions/m4/flow.py:144
A13: 67 | B13: 4 | C13: Station: state-choice reply | D13: VO_076 | E13: Maru | F13: Then hold the line. Order is all that's between this city and the pit. | G13: No matched audio | H13: ='Missing lines'!H71 -> Needs speaker check | I13: SPEAKER MISMATCH: manifest says MARU (reply), but _resolve_choice inserts this as BIRIBEL. Confirm/fix speaker before recording. Choice label is not separately spoken. | J13: src/missions/m4/flow.py:146
A14: 68 | B14: 4 | C14: Station: people-choice reply | D14: VO_077 | E14: Maru | F14: Good answer. Tools get pointed at the people too - remember that. | G14: No matched audio | H14: ='Missing lines'!H72 -> Needs speaker check | I14: SPEAKER MISMATCH: manifest says MARU (reply), but _resolve_choice inserts this as BIRIBEL. Confirm/fix speaker before recording. Choice label is not separately spoken. | J14: src/missions/m4/flow.py:146
A15: 69 | B15: 4 | C15: Station: liaison finished / jammer task | D15: VO_164 | E15: Maru | F15: Jammer's on the east rack. Break their comms before they organize. | G15: No matched audio | H15: ='Missing lines'!H73 -> To record | I15: Record clean; the game applies radio processing where needed. | J15: src/missions/m4/flow.py:280
A16: 70 | B16: 4 | C16: Station: reach jammer rack | D16: VO_171 | E16: Maru | F16: That's the rack. Plant it (E) and their comms go dark. | G16: No matched audio | H16: ='Missing lines'!H74 -> To record | I16: Record clean; the game applies radio processing where needed. | J16: src/missions/m4/flow.py:557
A17: 71 | B17: 4 | C17: Station: jammer installed / siege starts | D17: VO_173 | E17: Maru | F17: Jammer's live. Their comms are soup now. Get to the transmitter and hold it - when Retardovici gives the order, it has to reach every set in the country. | G17: No matched audio | H17: ='Missing lines'!H75 -> To record | I17: Record clean; the game applies radio processing where needed. | J17: src/missions/m4/flow.py:596
A18: 76 | B18: 4 | C18: Ending: Maru silhouette | D18: VO_081 | E18: Maru | F18: And the man on the screen smiles. The country is cheering the wrong name tonight. | G18: No matched audio | H18: ='Missing lines'!H80 -> To record | I18: Record clean; the game applies radio processing where needed. | J18: src/missions/m4/meta.py:161

Sheet Old Fisherman
A1: OLD FISHERMAN
A2: Separate from required actor recordings: text-only conversations, system captions, or implementation review.
A3: Character view. Update Tracking on the master Missing lines / Text-only review tab.
A4: Order | B4: Mission | C4: Scene / trigger | D4: ID | E4: Character | F4: Exact line / dialogue | G4: Gap / action | H4: Tracking | I4: Notes | J4: Source file : line
A5: 6 | B5: 1 | C5: Harbor: oil-rig attack | D5: TEXT_006 | E5: Old Fisherman | F5: Hear that engine? Too fast for a fishing boat. | G5: Text-only; no VO hook | H5: ='Text-only review'!H10 -> Review | I5: Timeline frame 135 (60 fps). _trigger_walk_dialogue only displays text; no manifest entry or voice-playback call. | J5: src/missions/walking_sim.py:1424
A6: 7 | B6: 1 | C6: Harbor: oil-rig attack | D6: TEXT_007 | E6: Old Fisherman | F6: They come in low during the rain. The rigs never see them until the first rocket. | G6: Text-only; no VO hook | H6: ='Text-only review'!H11 -> Review | I6: Timeline frame 360 (60 fps). _trigger_walk_dialogue only displays text; no manifest entry or voice-playback call. | J6: src/missions/walking_sim.py:1436
A7: 8 | B7: 1 | C7: Harbor: oil-rig attack | D7: TEXT_008 | E7: Old Fisherman | F7: There. Center rig's folding. | G7: Text-only; no VO hook | H7: ='Text-only review'!H12 -> Review | I7: Timeline frame 574 (60 fps). _trigger_walk_dialogue only displays text; no manifest entry or voice-playback call. | J7: src/missions/walking_sim.py:1466
A8: 9 | B8: 1 | C8: Harbor: oil-rig attack | D8: TEXT_009 | E8: Old Fisherman | F8: Left rig's falling into the sea. | G8: Text-only; no VO hook | H8: ='Text-only review'!H13 -> Review | I8: Timeline frame 795 (60 fps). _trigger_walk_dialogue only displays text; no manifest entry or voice-playback call. | J8: src/missions/walking_sim.py:1472
A9: 10 | B9: 1 | C9: Harbor: oil-rig attack | D9: TEXT_010 | E9: Old Fisherman | F9: Now the last one burns. Three fires on the horizon. | G9: Text-only; no VO hook | H9: ='Text-only review'!H14 -> Review | I9: Timeline frame 1030 (60 fps). _trigger_walk_dialogue only displays text; no manifest entry or voice-playback call. | J9: src/missions/walking_sim.py:1478
A10: 11 | B10: 1 | C10: Harbor: oil-rig attack | D10: TEXT_011 | E10: Old Fisherman | F10: Third time this month. KRAP watches until the oil stops moving. | G10: Text-only; no VO hook | H10: ='Text-only review'!H15 -> Review | I10: Timeline frame 1220 (60 fps). _trigger_walk_dialogue only displays text; no manifest entry or voice-playback call. | J10: src/missions/walking_sim.py:1452
A11: 12 | B11: 1 | C11: Harbor: oil-rig attack | D11: TEXT_012 | E11: Old Fisherman | F11: You're new. You'll learn. | G11: Text-only; no VO hook | H11: ='Text-only review'!H16 -> Review | I11: Timeline frame 1600 (60 fps). _trigger_walk_dialogue only displays text; no manifest entry or voice-playback call. | J11: src/missions/walking_sim.py:1459

Sheet Old Woman
A1: OLD WOMAN
A2: Separate from required actor recordings: text-only conversations, system captions, or implementation review.
A3: Character view. Update Tracking on the master Missing lines / Text-only review tab.
A4: Order | B4: Mission | C4: Scene / trigger | D4: ID | E4: Character | F4: Exact line / dialogue | G4: Gap / action | H4: Tracking | I4: Notes | J4: Source file : line
A5: 3 | B5: 1 | C5: Slum: conversation without rations | D5: TEXT_003 | E5: Old Woman | F5: They took everything... even the well water is contaminated. A dry throat and an empty stomach, that's our reward. | G5: Text-only; no VO hook | H5: ='Text-only review'!H7 -> Review | I5: No manifest entry and no voice-playback call. Add playback plus a VO ID only if you intend this NPC dialogue to be voiced. Optional interaction; local order depends on the player. | J5: src/missions/walking_sim.py:242
A6: 4 | B6: 1 | C6: Slum: food-gift response | D6: TEXT_004 | E6: Old Woman | F6: Bless you, soldier. Listen closely... The guards at the warehouse safe use a security passcode. I saw them write it down on notes: 7 - 4 - 2. Remember it well. | G6: Text-only; no VO hook | H6: ='Text-only review'!H8 -> Review | I6: No manifest entry and no voice-playback call. Add playback plus a VO ID only if you intend this NPC dialogue to be voiced. Optional interaction; local order depends on the player. | J6: src/missions/walking_sim.py:246
A7: 5 | B7: 1 | C7: Slum: repeat interaction | D7: TEXT_005 | E7: Old Woman | F7: Remember, the code to the notebook safe is 742. | G7: Text-only; no VO hook | H7: ='Text-only review'!H9 -> Review | I7: No manifest entry and no voice-playback call. Add playback plus a VO ID only if you intend this NPC dialogue to be voiced. Optional interaction; local order depends on the player. | J7: src/missions/walking_sim.py:252

Sheet PA System
A1: PA SYSTEM
A2: Mission 1 → Mission 4 · Optional branches are included; ordering within free-play phases can vary.
A3: Character view. Update Tracking on the master Missing lines / Text-only review tab.
A4: Order | B4: Mission | C4: Scene / trigger | D4: ID | E4: Character | F4: Exact line / dialogue | G4: Gap / action | H4: Tracking | I4: Notes | J4: Source file : line
A5: 24 | B5: 3 | C5: Black Ledger: secret detainee encounter | D5: VO_016 | E5: PA System | F5: Thirteen names closed. One name opened. | G5: No matched audio | H5: ='Missing lines'!H28 -> To record | I5: Record clean; the game applies radio processing where needed. Secret encounter: triggered after killing all ambient detainees. | J5: src/missions/m3/systems.py:2121

Sheet President Retardovici
A1: PRESIDENT RETARDOVICI
A2: Mission 1 → Mission 4 · Optional branches are included; ordering within free-play phases can vary.
A3: Character view. Update Tracking on the master Missing lines / Text-only review tab.
A4: Order | B4: Mission | C4: Scene / trigger | D4: ID | E4: Character | F4: Exact line / dialogue | G4: Gap / action | H4: Tracking | I4: Notes | J4: Source file : line
A5: 9 | B5: 2 | C5: Ending: state broadcast | D5: VO_001 | E5: President Retardovici | F5: Route 12 will be remembered as the day KRAP discipline failed the nation. | G5: No matched audio | H5: ='Missing lines'!H13 -> To record | I5: Record clean; the game applies radio processing where needed. | J5: src/missions/m2/meta.py:103

Sheet Presidential PA
A1: PRESIDENTIAL PA
A2: Mission 1 → Mission 4 · Optional branches are included; ordering within free-play phases can vary.
A3: Character view. Update Tracking on the master Missing lines / Text-only review tab.
A4: Order | B4: Mission | C4: Scene / trigger | D4: ID | E4: Character | F4: Exact line / dialogue | G4: Gap / action | H4: Tracking | I4: Notes | J4: Source file : line
A5: 63 | B5: 4 | C5: Aftermath streets: timed radio beat | D5: NEW_020 | E5: Presidential PA | F5: Citizens. Curfew holds. The Presidency has this under control. | G5: Not in voice manifest | H5: ='Missing lines'!H67 -> To record | I5: Add an entry to VOICE_LINES with a new VO ID; recording alone will not resolve this text. Speaker is PA in code; presidential channel, actor not explicitly named. | J5: src/missions/m4/flow.py:84
A6: 72 | B6: 4 | C6: Transmitter siege: arrest / stand-down broadcast | D6: NEW_021 | E6: Presidential PA | F6: All units. By order of the Presidency, garrison command is... recalibrated. | G6: Not in voice manifest | H6: ='Missing lines'!H76 -> To record | I6: Add an entry to VOICE_LINES with a new VO ID; recording alone will not resolve this text. Speaker is PA in code; presidential channel, actor not explicitly named. | J6: src/missions/m4/flow.py:334
A7: 73 | B7: 4 | C7: Transmitter siege: arrest / stand-down broadcast | D7: NEW_022 | E7: Presidential PA | F7: General Balaceanu is relieved of command and arrested. Escort him out. | G7: Not in voice manifest | H7: ='Missing lines'!H77 -> To record | I7: Add an entry to VOICE_LINES with a new VO ID; recording alone will not resolve this text. Speaker is PA in code; presidential channel, actor not explicitly named. | J7: src/missions/m4/flow.py:336

Sheet Seby
A1: SEBY
A2: Mission 1 → Mission 4 · Optional branches are included; ordering within free-play phases can vary.
A3: Character view. Update Tracking on the master Missing lines / Text-only review tab.
A4: Order | B4: Mission | C4: Scene / trigger | D4: ID | E4: Character | F4: Exact line / dialogue | G4: Gap / action | H4: Tracking | I4: Notes | J4: Source file : line
A5: 8 | B5: 2 | C5: Investigation: gantry flash preview | D5: NEW_008 | E5: Seby | F5: Did anyone else see that flash above the gantry? | G5: Not in voice manifest | H5: ='Missing lines'!H12 -> To record | I5: Add an entry to VOICE_LINES with a new VO ID; recording alone will not resolve this text. Travel triggers depend on route; shown in broad progression, not guaranteed trigger order. | J5: src/missions/m2/meta.py:625

Sheet System
A1: SYSTEM
A2: Separate from required actor recordings: text-only conversations, system captions, or implementation review.
A3: Character view. Update Tracking on the master Missing lines / Text-only review tab.
A4: Order | B4: Mission | C4: Scene / trigger | D4: ID | E4: Character | F4: Exact line / dialogue | G4: Gap / action | H4: Tracking | I4: Notes | J4: Source file : line
A5: 13 | B5: 2 | C5: System radio / objective notice | D5: TEXT_013 | E5: System | F5: IPA cleanup team in control sector. | G5: Generic system text; review | H5: ='Text-only review'!H17 -> Review | I5: Uses the radio-text channel but has no assigned actor or manifest entry. Voice only if wanted; add a VO ID first. | J5: src/missions/m2/sniper.py:1342
A6: 14 | B6: 2 | C6: System radio / objective notice | D6: TEXT_014 | E6: System | F6: Evidence transmitted. Move to extraction. | G6: Generic system text; review | H6: ='Text-only review'!H18 -> Review | I6: Uses the radio-text channel but has no assigned actor or manifest entry. Voice only if wanted; add a VO ID first. | J6: src/missions/m2/world.py:429
A7: 15 | B7: 2 | C7: Evidence: reinforcement notice (dynamic template) | D7: TEXT_015 | E7: System | F7: IPA {SECOND FINAL} WAVE INBOUND - {hostile count} HOSTILES | G7: Dynamic system text; review | H7: ='Text-only review'!H19 -> Review | I7: Interpolated wave label and hostile count; no fixed manifest lookup. Needs a deliberate dynamic/split-clip implementation if voiced. | J7: src/missions/m2/sniper.py:1429–1433
A8: 16 | B8: 2 | C8: System caption / display | D8: TEXT_016 | E8: System | F8: TRANSMISSION SENT ARCHIVE PARTIALLY CORRUPTED | G8: Caption; not actor dialogue | H8: ='Text-only review'!H20 -> Review | I8: On-screen transmission, monitor, or retry caption. No assigned character VO. Do not treat this as a required actor recording. | J8: src/missions/m2/meta.py:97
A9: 17 | B9: 3 | C9: System caption / display | D9: TEXT_017 | E9: System | F9: STATE ADDRESS, LIVE TONIGHT, 22:00 SUBJECT: ROUTE 12 PERPETRATOR | G9: Caption; not actor dialogue | H9: ='Text-only review'!H21 -> Review | I9: On-screen transmission, monitor, or retry caption. No assigned character VO. Do not treat this as a required actor recording. | J9: src/missions/m3/meta.py:106
A10: 18 | B10: 3 | C10: System caption / display | D10: TEXT_018 | E10: System | F10: ADDRESS COMPLETE. THE STUDIO IS THEIRS. FEED RELEASED - WING RESET. GO AGAIN. | G10: Caption; not actor dialogue | H10: ='Text-only review'!H22 -> Review | I10: On-screen transmission, monitor, or retry caption. No assigned character VO. Do not treat this as a required actor recording. | J10: src/missions/m3/meta.py:486
A11: 19 | B11: 4 | C11: System radio / objective notice | D11: TEXT_019 | E11: System | F11: Guns down. That's the President on the wire. The General's in cuffs. | G11: Generic system text; review | H11: ='Text-only review'!H23 -> Review | I11: Uses the radio-text channel but has no assigned actor or manifest entry. Voice only if wanted; add a VO ID first. | J11: src/missions/m4/flow.py:340
A12: 20 | B12: 4 | C12: System radio / objective notice | D12: TEXT_020 | E12: System | F12: The transmitter is live. Do not let it go dark. | G12: Generic system text; review | H12: ='Text-only review'!H24 -> Review | I12: Uses the radio-text channel but has no assigned actor or manifest entry. Voice only if wanted; add a VO ID first. | J12: src/missions/m4/flow.py:480
A13: 21 | B13: 4 | C13: System radio / objective notice | D13: TEXT_021 | E13: System | F13: All units - the studio transmitter is live. Do not let it go dark. | G13: Generic system text; review | H13: ='Text-only review'!H25 -> Review | I13: Uses the radio-text channel but has no assigned actor or manifest entry. Voice only if wanted; add a VO ID first. | J13: src/missions/m4/flow.py:607

Sheet Vasile
A1: VASILE
A2: Mission 1 → Mission 4 · Optional branches are included; ordering within free-play phases can vary.
A3: Character view. Update Tracking on the master Missing lines / Text-only review tab.
A4: Order | B4: Mission | C4: Scene / trigger | D4: ID | E4: Character | F4: Exact line / dialogue | G4: Gap / action | H4: Tracking | I4: Notes | J4: Source file : line
A5: 4 | B5: 2 | C5: Investigation: travel / equipment warning | D5: NEW_004 | E5: Vasile | F5: Route 12 opens into the checkpoint corridor. Stay slow. | G5: Not in voice manifest | H5: ='Missing lines'!H8 -> To record | I5: Add an entry to VOICE_LINES with a new VO ID; recording alone will not resolve this text. Travel triggers depend on route; shown in broad progression, not guaranteed trigger order. | J5: src/missions/m2/meta.py:579
A6: 7 | B6: 2 | C6: Investigation: travel / equipment warning | D6: NEW_007 | E6: Vasile | F6: Government tread, checkpoint equipment... keep your heads down. | G6: Not in voice manifest | H6: ='Missing lines'!H11 -> To record | I6: Add an entry to VOICE_LINES with a new VO ID; recording alone will not resolve this text. Travel triggers depend on route; shown in broad progression, not guaranteed trigger order. | J6: src/missions/m2/meta.py:614
A7: 46 | B7: 3 | C7: Kill Order: extraction window warning | D7: NEW_016 | E7: Vasile | F7: Volkov's patience is a resource. Spend it wisely. | G7: Not in voice manifest | H7: ='Missing lines'!H50 -> To record | I7: Add an entry to VOICE_LINES with a new VO ID; recording alone will not resolve this text. Threshold: 120 seconds remaining; can interleave combat beats. | J7: src/missions/m3/sweep.py:758
A8: 61 | B8: 4 | C8: Aftermath streets: timed radio beat | D8: NEW_018 | E8: Vasile | F8: This isn't a crackdown - it's a collapse. Stay off the boulevard. | G8: Not in voice manifest | H8: ='Missing lines'!H65 -> To record | I8: Add an entry to VOICE_LINES with a new VO ID; recording alone will not resolve this text. | J8: src/missions/m4/flow.py:78

Sheet Volkov
A1: VOLKOV
A2: Mission 1 → Mission 4 · Optional branches are included; ordering within free-play phases can vary.
A3: Character view. Update Tracking on the master Missing lines / Text-only review tab.
A4: Order | B4: Mission | C4: Scene / trigger | D4: ID | E4: Character | F4: Exact line / dialogue | G4: Gap / action | H4: Tracking | I4: Notes | J4: Source file : line
A5: 18 | B5: 3 | C5: Interrogation: Volkov breach | D5: VO_071 | E5: Volkov | F5: Door's kicked. Camera loop: four minutes, maybe less. I get you out, you get me clear. Move. | G5: No matched audio | H5: ='Missing lines'!H22 -> To record | I5: Record clean; the game applies radio processing where needed. | J5: src/missions/m3/meta.py:421
A6: 19 | B6: 3 | C6: Interrogation: escape instruction | D6: VO_072 | E6: Volkov | F6: I came in through their own back door. Same way out, if you keep up. Move, operator. Move. | G6: No matched audio | H6: ='Missing lines'!H23 -> To record | I6: Record clean; the game applies radio processing where needed. | J6: src/missions/m3/meta.py:423
A7: 20 | B7: 3 | C7: Interrogation breach: alarm | D7: VO_147 | E7: Volkov | F7: Too loud now. Move! | G7: No matched audio | H7: ='Missing lines'!H24 -> To record | I7: Record clean; the game applies radio processing where needed. | J7: src/missions/m3/interrog.py:405
A8: 21 | B8: 3 | C8: Breakout: Volkov draws guards away | D8: VO_148 | E8: Volkov | F8: Alarm's up. I'll draw them off, you move. | G8: No matched audio | H8: ='Missing lines'!H25 -> To record | I8: Record clean; the game applies radio processing where needed. | J8: src/missions/m3/interrog.py:490
A9: 22 | B9: 3 | C9: Breakout checkpoint: resume bark | D9: VO_131 | E9: Volkov | F9: I bought you seconds. Make the leg useful, then move. | G9: No matched audio | H9: ='Missing lines'!H26 -> To record | I9: Record clean; the game applies radio processing where needed. Checkpoint/resume path, not a mandatory fresh-run beat. | J9: src/missions/m3/flow.py:441
A10: 23 | B10: 3 | C10: Breakout: exit / south hall | D10: VO_135 | E10: Volkov | F10: They're awake now. South hall, move. | G10: No matched audio | H10: ='Missing lines'!H27 -> To record | I10: Record clean; the game applies radio processing where needed. | J10: src/missions/m3/flow.py:1276
A11: 25 | B11: 3 | C11: Breakout → Comms: radio handoff | D11: VO_055 | E11: Volkov | F11: Biribel! Take the radio. I draw them off, you get the relay alive. | G11: No matched audio | H11: ='Missing lines'!H29 -> To record | I11: Record clean; the game applies radio processing where needed. | J11: src/missions/m3/meta.py:231
A12: 26 | B12: 3 | C12: Comms: optional ammo resupply cutscene | D12: VO_057 | E12: Volkov | F12: Out? Here. Two more. Make them count. | G12: No matched audio | H12: ='Missing lines'!H30 -> To record | I12: Record clean; the game applies radio processing where needed. Conditional gameplay / route; timing varies with play. | J12: src/missions/m3/meta.py:239
A13: 27 | B13: 3 | C13: Comms: rotating ammo-resupply bark | D13: NEW_009 | E13: Volkov | F13: Out?! Catch! | G13: Not in voice manifest | H13: ='Missing lines'!H31 -> To record | I13: Add an entry to VOICE_LINES with a new VO ID; recording alone will not resolve this text. Rotates with resupplies; can interleave other phase dialogue. | J13: src/missions/m3/flow.py:1248
A14: 28 | B14: 3 | C14: Comms: rotating ammo-resupply bark | D14: NEW_010 | E14: Volkov | F14: Mag up, move! | G14: Not in voice manifest | H14: ='Missing lines'!H32 -> To record | I14: Add an entry to VOICE_LINES with a new VO ID; recording alone will not resolve this text. Rotates with resupplies; can interleave other phase dialogue. | J14: src/missions/m3/flow.py:1249
A15: 29 | B15: 3 | C15: Comms: rotating ammo-resupply bark | D15: NEW_011 | E15: Volkov | F15: Stay lethal! | G15: Not in voice manifest | H15: ='Missing lines'!H33 -> To record | I15: Add an entry to VOICE_LINES with a new VO ID; recording alone will not resolve this text. Rotates with resupplies; can interleave other phase dialogue. | J15: src/missions/m3/flow.py:1250
A16: 30 | B16: 3 | C16: Comms: authorization acquired | D16: VO_129 | E16: Volkov | F16: Authorization is good. Get back to the relay. | G16: No matched audio | H16: ='Missing lines'!H34 -> To record | I16: Record clean; the game applies radio processing where needed. Also covers duplicate VO_162. | J16: src/missions/m3/systems.py:3045
A17: 31 | B17: 3 | C17: Comms → Archives: ally joins | D17: VO_058 | E17: Volkov | F17: On your six. Move. | G17: No matched audio | H17: ='Missing lines'!H35 -> To record | I17: Record clean; the game applies radio processing where needed. | J17: src/missions/m3/meta.py:251
A18: 32 | B18: 3 | C18: Archives checkpoint: resume bark | D18: VO_133 | E18: Volkov | F18: Back on your six. Call when you're dry, I've got mags. | G18: No matched audio | H18: ='Missing lines'!H36 -> To record | I18: Record clean; the game applies radio processing where needed. Checkpoint/resume path, not a mandatory fresh-run beat. | J18: src/missions/m3/flow.py:627
A19: 33 | B19: 3 | C19: Archives: phase entry | D19: VO_137 | E19: Volkov | F19: I'm with you. Stacks west, vault northeast. Don't dry the mag, I'll toss you one. | G19: No matched audio | H19: ='Missing lines'!H37 -> To record | I19: Record clean; the game applies radio processing where needed. | J19: src/missions/m3/flow.py:1410
A20: 34 | B20: 3 | C20: Archives: rotating ammo-resupply bark | D20: NEW_012 | E20: Volkov | F20: Dry? Catch, don't make me regret this! | G20: Not in voice manifest | H20: ='Missing lines'!H38 -> To record | I20: Add an entry to VOICE_LINES with a new VO ID; recording alone will not resolve this text. Rotates with resupplies; can interleave other phase dialogue. | J20: src/missions/m3/flow.py:1242
A21: 35 | B21: 3 | C21: Archives: rotating ammo-resupply bark | D21: NEW_013 | E21: Volkov | F21: Mag! Keep pushing the stacks! | G21: Not in voice manifest | H21: ='Missing lines'!H39 -> To record | I21: Add an entry to VOICE_LINES with a new VO ID; recording alone will not resolve this text. Rotates with resupplies; can interleave other phase dialogue. | J21: src/missions/m3/flow.py:1243
A22: 36 | B22: 3 | C22: Archives: rotating ammo-resupply bark | D22: NEW_014 | E22: Volkov | F22: Last spare. Make them count! | G22: Not in voice manifest | H22: ='Missing lines'!H40 -> To record | I22: Add an entry to VOICE_LINES with a new VO ID; recording alone will not resolve this text. Rotates with resupplies; can interleave other phase dialogue. | J22: src/missions/m3/flow.py:1244
A23: 38 | B23: 3 | C23: Archives: Vostral pickup / exit | D23: VO_144 | E23: Volkov | F23: I've got your back to the door. Go. | G23: No matched audio | H23: ='Missing lines'!H42 -> To record | I23: Record clean; the game applies radio processing where needed. | J23: src/missions/m3/flow.py:1879
A24: 40 | B24: 3 | C24: Archives → Kill Order: Volkov | D24: VO_060 | E24: Volkov | F24: My van's still staged at the dock, I haven't bailed on you yet. Through that smoke, friend, and don't make me regret it. | G24: No matched audio | H24: ='Missing lines'!H44 -> To record | I24: Record clean; the game applies radio processing where needed. | J24: src/missions/m3/meta.py:264
A25: 43 | B25: 3 | C25: Kill Order: shield contact | D25: VO_160 | E25: Volkov | F25: Contact - shield point ahead! His sight cone is narrow: go around it, friend. | G25: No matched audio | H25: ='Missing lines'!H47 -> To record | I25: Record clean; the game applies radio processing where needed. Conditional gameplay / route; timing varies with play. | J25: src/missions/m3/sweep.py:1044
A26: 44 | B26: 3 | C26: Kill Order: extraction window warning | D26: NEW_015 | E26: Volkov | F26: Window's closing. My engine idles for no one - not even you. | G26: Not in voice manifest | H26: ='Missing lines'!H48 -> To record | I26: Add an entry to VOICE_LINES with a new VO ID; recording alone will not resolve this text. Threshold: 210 seconds remaining; can interleave combat beats. | J26: src/missions/m3/sweep.py:755
A27: 45 | B27: 3 | C27: Kill Order: shield point cleared | D27: VO_149 | E27: Volkov | F27: Shield point is down - the south is open. Push, friend. | G27: No matched audio | H27: ='Missing lines'!H49 -> To record | I27: Record clean; the game applies radio processing where needed. Conditional gameplay / route; timing varies with play. | J27: src/missions/m3/sweep.py:287
A28: 47 | B28: 3 | C28: Kill Order: extraction window warning | D28: NEW_017 | E28: Volkov | F28: Forty-five seconds. Then I'm a memory. | G28: Not in voice manifest | H28: ='Missing lines'!H51 -> To record | I28: Add an entry to VOICE_LINES with a new VO ID; recording alone will not resolve this text. Threshold: 45 seconds remaining; can interleave combat beats. | J28: src/missions/m3/sweep.py:760
A29: 49 | B29: 3 | C29: Kill Order: marksman down / van available | D29: VO_151 | E29: Volkov | F29: Their marksman is gone. Dock gates are open - I'll cycle the door when you get there. | G29: No matched audio | H29: ='Missing lines'!H53 -> To record | I29: Record clean; the game applies radio processing where needed. Conditional gameplay / route; timing varies with play. | J29: src/missions/m3/sweep.py:293
A30: 50 | B30: 3 | C30: Kill Order: Volkov window expires | D30: VO_154 | E30: Volkov | F30: ...The van's gone. Dock crane, roof line - you're resourceful. Sorry, friend. | G30: No matched audio | H30: ='Missing lines'!H54 -> To record | I30: Record clean; the game applies radio processing where needed. Conditional gameplay / route; timing varies with play. | J30: src/missions/m3/sweep.py:769
A31: 51 | B31: 3 | C31: Dock holdout: van branch | D31: VO_155 | E31: Volkov | F31: Behind me. Door cycles in forty-five. I'll keep them off it. | G31: No matched audio | H31: ='Missing lines'!H55 -> To record | I31: Record clean; the game applies radio processing where needed. Conditional gameplay / route; timing varies with play. | J31: src/missions/m3/sweep.py:874
A32: 53 | B32: 3 | C32: Dock holdout: van gate still blocked | D32: VO_157 | E32: Volkov | F32: Van's held - sweep teams still on you. Clear them, then we roll! | G32: No matched audio | H32: ='Missing lines'!H57 -> To record | I32: Record clean; the game applies radio processing where needed. Conditional gameplay / route; timing varies with play. | J32: src/missions/m3/sweep.py:955
A33: 55 | B33: 3 | C33: Exfil: van branch | D33: VO_159 | E33: Volkov | F33: File's aboard. I drive, you watch the mirrors. DRIVE! | G33: No matched audio | H33: ='Missing lines'!H59 -> To record | I33: Record clean; the game applies radio processing where needed. Conditional gameplay / route; timing varies with play. | J33: src/missions/m3/sweep.py:988
A34: 57 | B34: 3 | C34: Broadcast: phase entry | D34: VO_140 | E34: Volkov | F34: I'm on your six. You take the desk, I'll hold the floor. | G34: No matched audio | H34: ='Missing lines'!H61 -> To record | I34: Record clean; the game applies radio processing where needed. | J34: src/missions/m3/flow.py:1454
A35: 60 | B35: 3 | C35: Ending: booth conversation | D35: VO_052 | E35: Volkov | F35: Six years he spent building it. You read it in one minute. | G35: No matched audio | H35: ='Missing lines'!H64 -> To record | I35: Record clean; the game applies radio processing where needed. | J35: src/missions/m3/meta.py:154

Sheet Registry audit
A1: VOICE REGISTRY · AUDIO MATCH AUDIT
A2: All 173 manifest IDs. Audio matched means the game matcher finds a file, not that the speech content was verified.
A4: VO ID | B4: Character | C4: Manifest speaker | D4: Manifest text | E4: Audit result | F4: Matched file | G4: Script references | H4: Notes
A5: VO_001 | B5: President Retardovici | C5: PRESIDENT RETARDOVICI | D5: Route 12 will be remembered as the day KRAP discipline failed the nation. | E5: Missing audio | G5: src/missions/m2/meta.py:103 | H5: Included in Missing lines.
A6: VO_002 | B6: Balaceanu | C6: BALACEANU | D6: Effective immediately, KRAP operations in the highway corridor fall under government review. | E6: Missing audio | G6: src/missions/m2/meta.py:109 | H6: Included in Missing lines.
A7: VO_003 | B7: IPA Dispatch | C7: IPA DISPATCH | D7: All units. The KRAP operator is the primary suspect. Bring him in. Authorization IPA-Code Omega. | E7: Missing audio | G7: src/missions/m2/meta.py:141 | H7: Included in Missing lines.
A8: VO_004 | B8: Balaceanu | C8: BALACEANU (PA) | D8: Sweep teams, report. The prisoner carries state property. My address begins at 22:00, and he will not outlive it. | E8: Missing audio | G8: src/missions/m3/flow.py:955 | H8: Included in Missing lines.
